<?xml version="1.0" encoding="utf-8"?>
<!-- This URDF was automatically created by SolidWorks to URDF Exporter! Originally created by Stephen Brawner (brawner@gmail.com) 
     Commit Version: 1.6.0-4-g7f85cfe  Build Version: 1.6.7995.38578
     For more information, please see http://wiki.ros.org/sw_urdf_exporter -->
<robot
  name="hapticdevice_URDF">
  <link name="world" />
  <link
    name="base_link">
    <inertial>
      <origin
        xyz="-4.1176E-09 0.044026 -0.010769"
        rpy="0 0 0" />
      <mass
        value="0.35643" />
      <inertia
        ixx="0.00035084"
        ixy="3.3904E-11"
        ixz="3.1619E-10"
        iyy="0.00021322"
        iyz="1.1133E-05"
        izz="0.00028173" />
    </inertial>
    <visual>
      <origin
        xyz="0 0 0"
        rpy="0 0 0" />
      <geometry>
        <mesh
          filename="package://hapticdevice_URDF/meshes/base_link.STL" />
      </geometry>
      <material
        name="">
        <color
          rgba="0.75294 0.75294 0.75294 1" />
      </material>
    </visual>
    <collision>
      <origin
        xyz="0 0 0"
        rpy="0 0 0" />
      <geometry>
        <mesh
          filename="package://hapticdevice_URDF/meshes/base_link.STL" />
      </geometry>
    </collision>
  </link>
  <link
    name="link1">
    <inertial>
      <origin
        xyz="-3.8796E-05 0.019458 -0.029667"
        rpy="0 0 0" />
      <mass
        value="0.30565" />
      <inertia
        ixx="0.00011179"
        ixy="2.5773E-08"
        ixz="-6.3437E-08"
        iyy="7.4244E-05"
        iyz="7.2778E-06"
        izz="0.00010005" />
    </inertial>
    <visual>
      <origin
        xyz="0 0 0"
        rpy="0 0 0" />
      <geometry>
        <mesh
          filename="package://hapticdevice_URDF/meshes/link1.STL" />
      </geometry>
      <material
        name="">
        <color
          rgba="0.75294 0.75294 0.75294 1" />
      </material>
    </visual>
    <collision>
      <origin
        xyz="0 0 0"
        rpy="0 0 0" />
      <geometry>
        <mesh
          filename="package://hapticdevice_URDF/meshes/link1.STL" />
      </geometry>
    </collision>
  </link>
  <joint
    name="world_to_base"
    type="fixed">
    <origin
      xyz="0 0 0"
      rpy="0 0 0" />
    <parent
      link="world" />
    <child
      link="base_link" />
  </joint>
  <joint
    name="joint1"
    type="continuous">
    <origin
      xyz="0 -0.081 0"
      rpy="1.5708 -1.5708 0" />
    <parent
      link="base_link" />
    <child
      link="link1" />
    <axis
      xyz="0 0 1" />
    <limit
      effort="10"
      velocity="5" />
  </joint>
  <link
    name="link2">
    <inertial>
      <origin
        xyz="-0.00010508 0.04925 0.06575"
        rpy="0 0 0" />
      <mass
        value="0.20572" />
      <inertia
        ixx="0.00085531"
        ixy="-4.4914E-07"
        ixz="2.2332E-08"
        iyy="3.069E-05"
        iyz="-3.616E-07"
        izz="0.00086051" />
    </inertial>
    <visual>
      <origin
        xyz="0 0 0"
        rpy="0 0 0" />
      <geometry>
        <mesh
          filename="package://hapticdevice_URDF/meshes/link2.STL" />
      </geometry>
      <material
        name="">
        <color
          rgba="0.75294 0.75294 0.75294 1" />
      </material>
    </visual>
    <collision>
      <origin
        xyz="0 0 0"
        rpy="0 0 0" />
      <geometry>
        <mesh
          filename="package://hapticdevice_URDF/meshes/link2.STL" />
      </geometry>
    </collision>
  </link>
  <joint
    name="joint2"
    type="continuous">
    <origin
      xyz="0 0 0"
      rpy="1.5708 -1.5708 0" />
    <parent
      link="link1" />
    <child
      link="link2" />
    <axis
      xyz="0 0 1" />
    <limit
      effort="10"
      velocity="5" />
  </joint>
  <link
    name="link3">
    <inertial>
      <origin
        xyz="-0.087585 0.0021428 -0.042934"
        rpy="0 0 0" />
      <mass
        value="0.092048" />
      <inertia
        ixx="4.7483E-05"
        ixy="-5.1306E-20"
        ixz="6.964E-06"
        iyy="5.0158E-05"
        iyz="4.5003E-07"
        izz="2.1578E-05" />
    </inertial>
    <visual>
      <origin
        xyz="0 0 0"
        rpy="0 0 0" />
      <geometry>
        <mesh
          filename="package://hapticdevice_URDF/meshes/link3.STL" />
      </geometry>
      <material
        name="">
        <color
          rgba="0.75294 0.75294 0.75294 1" />
      </material>
    </visual>
    <collision>
      <origin
        xyz="0 0 0"
        rpy="0 0 0" />
      <geometry>
        <mesh
          filename="package://hapticdevice_URDF/meshes/link3.STL" />
      </geometry>
    </collision>
  </link>
  <joint
    name="joint3"
    type="prismatic">
    <origin
      xyz="-0.00013 -0.12781 0"
      rpy="1.5708 1.5708 0" />
    <parent
      link="link2" />
    <child
      link="link3" />
    <axis
      xyz="0 0 1" />
    <limit
      lower="0"
      upper="0.1242"
      effort="100"
      velocity="0.5" />
  </joint>
  <link
    name="link4">
    <inertial>
      <origin
        xyz="-3.859E-08 0.00013 -0.039537"
        rpy="0 0 0" />
      <mass
        value="0.11363" />
      <inertia
        ixx="0.00019291"
        ixy="5.6083E-19"
        ixz="-1.2656E-20"
        iyy="5.7212E-05"
        iyz="-3.7223E-19"
        izz="0.00015799" />
    </inertial>
    <visual>
      <origin
        xyz="0 0 0"
        rpy="0 0 0" />
      <geometry>
        <mesh
          filename="package://hapticdevice_URDF/meshes/link4.STL" />
      </geometry>
      <material
        name="">
        <color
          rgba="0.75294 0.75294 0.75294 1" />
      </material>
    </visual>
    <collision>
      <origin
        xyz="0 0 0"
        rpy="0 0 0" />
      <geometry>
        <mesh
          filename="package://hapticdevice_URDF/meshes/link4.STL" />
      </geometry>
    </collision>
  </link>
  <joint
    name="joint4"
    type="continuous">
    <origin
      xyz="0 0 0"
      rpy="0 1.5708 0" />
    <parent
      link="link3" />
    <child
      link="link4" />
    <axis
      xyz="0 0 1" />
    <limit
      effort="10"
      velocity="5" />
  </joint>
  <link
    name="link5">
    <inertial>
      <origin
        xyz="-1.9571E-18 -0.0098952 1.1102E-16"
        rpy="0 0 0" />
      <mass
        value="0.088049" />
      <inertia
        ixx="3.73E-05"
        ixy="-1.0453E-20"
        ixz="-5.4415E-20"
        iyy="3.8214E-05"
        iyz="-3.6354E-20"
        izz="1.7833E-05" />
    </inertial>
    <visual>
      <origin
        xyz="0 0 0"
        rpy="0 0 0" />
      <geometry>
        <mesh
          filename="package://hapticdevice_URDF/meshes/link5.STL" />
      </geometry>
      <material
        name="">
        <color
          rgba="0.75294 0.75294 0.75294 1" />
      </material>
    </visual>
    <collision>
      <origin
        xyz="0 0 0"
        rpy="0 0 0" />
      <geometry>
        <mesh
          filename="package://hapticdevice_URDF/meshes/link5.STL" />
      </geometry>
    </collision>
  </link>
  <joint
    name="joint5"
    type="continuous">
    <origin
      xyz="0 0 0"
      rpy="1.5708 -1.5708 0" />
    <parent
      link="link4" />
    <child
      link="link5" />
    <axis
      xyz="0 0 1" />
    <limit
      effort="10"
      velocity="5" />
  </joint>
  <link
    name="link6">
    <inertial>
      <origin
        xyz="7.7961E-06 -1.6354E-05 0.056894"
        rpy="0 0 0" />
      <mass
        value="0.14641" />
      <inertia
        ixx="0.00012747"
        ixy="-2.9587E-08"
        ixz="1.3549E-08"
        iyy="8.8676E-05"
        iyz="-5.0456E-08"
        izz="5.803E-05" />
    </inertial>
    <visual>
      <origin
        xyz="0 0 0"
        rpy="0 0 0" />
      <geometry>
        <mesh
          filename="package://hapticdevice_URDF/meshes/link6.STL" />
      </geometry>
      <material
        name="">
        <color
          rgba="0.75294 0.75294 0.75294 1" />
      </material>
    </visual>
    <collision>
      <origin
        xyz="0 0 0"
        rpy="0 0 0" />
      <geometry>
        <mesh
          filename="package://hapticdevice_URDF/meshes/link6.STL" />
      </geometry>
    </collision>
  </link>
  <joint
    name="joint6"
    type="continuous">
    <origin
      xyz="0 0 0"
      rpy="-1.5708 0 0" />
    <parent
      link="link5" />
    <child
      link="link6" />
    <axis
      xyz="0 0 1" />
    <limit
      effort="10"
      velocity="5" />
  </joint>
  <link
    name="link3b">
    <inertial>
      <origin
        xyz="-0.038751 -0.015113 -0.18115"
        rpy="0 0 0" />
      <mass
        value="0.10018" />
      <inertia
        ixx="2.8595E-05"
        ixy="-7.3251E-20"
        ixz="-2.1292E-21"
        iyy="4.7627E-05"
        iyz="4.5003E-07"
        izz="3.7548E-05" />
    </inertial>
    <visual>
      <origin
        xyz="0 0 0"
        rpy="0 0 0" />
      <geometry>
        <mesh
          filename="package://hapticdevice_URDF/meshes/link3b.STL" />
      </geometry>
      <material
        name="">
        <color
          rgba="0.75294 0.75294 0.75294 1" />
      </material>
    </visual>
    <collision>
      <origin
        xyz="0 0 0"
        rpy="0 0 0" />
      <geometry>
        <mesh
          filename="package://hapticdevice_URDF/meshes/link3b.STL" />
      </geometry>
    </collision>
  </link>
  <joint
    name="joint3b"
    type="prismatic">
    <origin
      xyz="-0.00013 -0.12781 0"
      rpy="1.5708 1.5708 0" />
    <parent
      link="link2" />
    <child
      link="link3b" />
    <axis
      xyz="0 0 1" />
    <limit
      lower="-0.1242"
      upper="0"
      effort="100"
      velocity="0.5" />
    <mimic
      joint="joint3"
      multiplier="-1"
      offset="0" />
  </joint>
  <ros2_control name="GazeboSimSystem" type="system">
    <hardware>
      <plugin>gz_ros2_control/GazeboSimSystem</plugin>
    </hardware>
    <joint name="joint1">
      <command_interface name="position"/>
      <state_interface name="position">
        <param name="initial_value">0.0</param>
      </state_interface>
      <state_interface name="velocity"/>
      <state_interface name="effort"/>
    </joint>
    <joint name="joint2">
      <command_interface name="position"/>
      <state_interface name="position">
        <param name="initial_value">0.0</param>
      </state_interface>
      <state_interface name="velocity"/>
      <state_interface name="effort"/>
    </joint>
    <joint name="joint3">
      <command_interface name="position">
        <param name="min">0.0</param>
        <param name="max">0.1242</param>
      </command_interface>
      <state_interface name="position">
        <param name="initial_value">0.0</param>
      </state_interface>
      <state_interface name="velocity"/>
      <state_interface name="effort"/>
    </joint>
    <joint name="joint4">
      <command_interface name="position"/>
      <state_interface name="position">
        <param name="initial_value">0.0</param>
      </state_interface>
      <state_interface name="velocity"/>
      <state_interface name="effort"/>
    </joint>
    <joint name="joint5">
      <command_interface name="position"/>
      <state_interface name="position">
        <param name="initial_value">0.0</param>
      </state_interface>
      <state_interface name="velocity"/>
      <state_interface name="effort"/>
    </joint>
    <joint name="joint6">
      <command_interface name="position"/>
      <state_interface name="position">
        <param name="initial_value">0.0</param>
      </state_interface>
      <state_interface name="velocity"/>
      <state_interface name="effort"/>
    </joint>
    <joint name="joint3b">
      <param name="mimic">joint3</param>
      <param name="multiplier">-1</param>
      <state_interface name="position">
        <param name="initial_value">0.0</param>
      </state_interface>
      <state_interface name="velocity"/>
      <state_interface name="effort"/>
    </joint>
  </ros2_control>
  <gazebo>
    <plugin
      filename="libgz_ros2_control-system.so"
      name="gz_ros2_control::GazeboSimROS2ControlPlugin">
      <parameters>__HAPTICDEVICE_CONTROLLERS_FILE__</parameters>
      <hold_joints>true</hold_joints>
    </plugin>
  </gazebo>
</robot>
